<?xml version="1.0"?>
<robot name="myfirst">

    <material name="red">
        <color rgba="1.0 0.1 0.0 1.0"/>
    </material>

    <material name="wheel_color">
        <color rgba="0.0 0.9 0.7.0 1.0"/>
    </material>


    <link name="base_link">
        <visual>
            <geometry>
                <mesh filename="package://umnitsa_gs/meshes/umnitsa_nano_body.stl"/>
            </geometry>
            <material name="red"/>
        </visual>
        <collision>
            <geometry>
                <cylinder length="0.3" radius="0.15"/>
                
            </geometry>
            <origin xyz="0.0 0 0.15"/>
            <material>
                <color rgba="0.0 1.0 0.2 1.0"/>
            </material>
        </collision>
    </link>

    <link name="laser">

    </link>

    <joint name="base_to_laser" type="fixed">
        <parent link="base_link"/>
        <child link="laser"/>
        <origin rpy="0 0 3.14159" xyz="-0.0 0.0 0.215"/>
    </joint>


    <link name="wheel_1">
        <visual>
            <geometry>
                <mesh filename="package://umnitsa_gs/meshes/omni_wheel.stl"/>
            </geometry>
            <material name="wheel_color"/>
            <origin rpy="-1.5708 0 1.5708" xyz="0 0 0"/>
        </visual>
    </link>

    <joint name="base_to_wheel_1" type="continuous">
        <parent link="base_link"/>
        <child link="wheel_1"/>
        <origin rpy="0 0 5.498" xyz="0.075 -0.075 0.0376"/>
    </joint>

    <link name="wheel_2">
        <visual>
            <geometry>
                <mesh filename="package://umnitsa_gs/meshes/omni_wheel.stl"/>
            </geometry>
            <material name="wheel_color"/>
            <origin rpy="-1.5708 0 1.5708" xyz="0 0 0"/>
        </visual>
    </link>

    <joint name="base_to_wheel_2" type="continuous">
        <parent link="base_link"/>
        <child link="wheel_2"/>
        <origin rpy="0 0 2.356" xyz="-0.075 0.075 0.0376"/>
    </joint>


    <link name="wheel_3">
        <visual>
            <geometry>
                <mesh filename="package://umnitsa_gs/meshes/omni_wheel.stl"/>
            </geometry>
            <material name="wheel_color"/>
            <origin rpy="-1.5708 0 1.5708" xyz="0 0 0"/>
        </visual>
    </link>

    <joint name="base_to_wheel_3" type="continuous">
        <parent link="base_link"/>
        <child link="wheel_3"/>
        <origin rpy="0 0 0.785" xyz="0.075 0.075 0.0376"/>
    </joint>

    <link name="wheel_4">
        <visual>
            <geometry>
                <mesh filename="package://umnitsa_gs/meshes/omni_wheel.stl"/>
            </geometry>
            <material name="wheel_color"/>
            <origin rpy="-1.5708 0 1.5708" xyz="0 0 0"/>
        </visual>
    </link>

    <joint name="base_to_wheel_4" type="continuous">
        <parent link="base_link"/>
        <child link="wheel_4"/>
        <origin rpy="0 0 3.927" xyz="-0.075 -0.075 0.0376"/>
    </joint>












</robot>